Traceback (most recent call last):
  File "/opt/hostedtoolcache/Python/3.9.23/x64/lib/python3.9/site-packages/jupyter_core/utils/__init__.py", line 154, in wrapped
    asyncio.get_running_loop()
RuntimeError: no running event loop

During handling of the above exception, another exception occurred:

Traceback (most recent call last):
  File "/opt/hostedtoolcache/Python/3.9.23/x64/lib/python3.9/site-packages/jupyter_cache/executors/utils.py", line 58, in single_nb_execution
    executenb(
  File "/opt/hostedtoolcache/Python/3.9.23/x64/lib/python3.9/site-packages/nbclient/client.py", line 1319, in execute
    return NotebookClient(nb=nb, resources=resources, km=km, **kwargs).execute()
  File "/opt/hostedtoolcache/Python/3.9.23/x64/lib/python3.9/site-packages/jupyter_core/utils/__init__.py", line 158, in wrapped
    return loop.run_until_complete(inner)
  File "/opt/hostedtoolcache/Python/3.9.23/x64/lib/python3.9/asyncio/base_events.py", line 647, in run_until_complete
    return future.result()
  File "/opt/hostedtoolcache/Python/3.9.23/x64/lib/python3.9/site-packages/nbclient/client.py", line 709, in async_execute
    await self.async_execute_cell(
  File "/opt/hostedtoolcache/Python/3.9.23/x64/lib/python3.9/site-packages/nbclient/client.py", line 1062, in async_execute_cell
    await self._check_raise_for_error(cell, cell_index, exec_reply)
  File "/opt/hostedtoolcache/Python/3.9.23/x64/lib/python3.9/site-packages/nbclient/client.py", line 918, in _check_raise_for_error
    raise CellExecutionError.from_cell_and_msg(cell, exec_reply_content)
nbclient.exceptions.CellExecutionError: An error occurred while executing the following cell:
------------------
import pytensor.tensor as pt
import arviz as az
import matplotlib.pyplot as plt
import numpy as np
import pandas as pd
import seaborn as sns
from scipy.stats import norm

import pymc as pm

sns.set_context('talk')
------------------


[0;31m---------------------------------------------------------------------------[0m
[0;31mModuleNotFoundError[0m                       Traceback (most recent call last)
Cell [0;32mIn[1], line 1[0m
[0;32m----> 1[0m [38;5;28;01mimport[39;00m[38;5;250m [39m[38;5;21;01mpytensor[39;00m[38;5;21;01m.[39;00m[38;5;21;01mtensor[39;00m[38;5;250m [39m[38;5;28;01mas[39;00m[38;5;250m [39m[38;5;21;01mpt[39;00m
[1;32m      2[0m [38;5;28;01mimport[39;00m[38;5;250m [39m[38;5;21;01marviz[39;00m[38;5;250m [39m[38;5;28;01mas[39;00m[38;5;250m [39m[38;5;21;01maz[39;00m
[1;32m      3[0m [38;5;28;01mimport[39;00m[38;5;250m [39m[38;5;21;01mmatplotlib[39;00m[38;5;21;01m.[39;00m[38;5;21;01mpyplot[39;00m[38;5;250m [39m[38;5;28;01mas[39;00m[38;5;250m [39m[38;5;21;01mplt[39;00m

[0;31mModuleNotFoundError[0m: No module named 'pytensor'

